Workbook
Name Slicer_Energy_Category: #N/A
Name Slicer_Months__Log_Date: #N/A

Sheet pivot table
P1: KPIS
A2: Seasonal Energy Consumption Pattern | P2: No of Maintenance
A3: Row Labels | B3: Sum of Filled Energy Consumption | P3: 345 | Q3: =GETPIVOTDATA("Maintenance ID",$P$2) -> 345
A4: Jan | B4: 6189.3269
A5: Feb | B5: 7316.5318
A6: Mar | B6: 5342.9989
A7: Apr | B7: 4697.2471 | P7: Sum of Filled Energy Consumption
A8: May | B8: 5300.0491 | P8: 72761.604 | Q8: =GETPIVOTDATA("Filled Energy Consumption",$P$7) -> 72761.604
A9: Jun | B9: 6639.9979
A10: Jul | B10: 6951.2032
A11: Aug | B11: 7029.0162 | P11: Average HVAC Setting
A12: Sep | B12: 5551.9971 | P12: 3.047037 | Q12: =GETPIVOTDATA("HVAC Setting",$P$11) -> 3.047037
A13: Oct | B13: 5153.2933
A14: Nov | B14: 5348.3908
A15: Dec | B15: 7241.5513
A16: Grand Total | B16: 72761.604 | P16: Average Temperature
P17: 69.787605 | Q17: =GETPIVOTDATA("Temperature",$P$16) -> 69.787605
A23: Seasonal Energy Consumption Pattern by Day
A24: Row Labels | B24: Average of Filled Energy Consumption
A25: 1 | B25: 17.547121
A26: 2 | B26: 17.508535
A27: 3 | B27: 17.516404
A28: 4 | B28: 18.481502
A29: 5 | B29: 17.169202
A30: 6 | B30: 19.034446
A31: 7 | B31: 17.883119
A32: 8 | B32: 18.645528
A33: 9 | B33: 17.55574
A34: 10 | B34: 17.9824
A35: 11 | B35: 17.890429
A36: 12 | B36: 18.025029
... A48: 24 | B48: 18.176408
A49: Grand Total | B49: 17.965828
A52: Time-of-Day Consumption Patterns
A53: Row Labels | B53: Average EC
A54: Evening | B54: 25.626313
A55: Afternoon | B55: 17.784512
A56: Morning | B56: 17.230257
A57: Night | B57: 15.041078
A58: Grand Total | B58: 17.965828
...

Sheet sensor_data
A1: Timestamp | B1: Column3 | C1: Time of Day | D1: Column2 | E1: Day | F1: Unit ID | G1: Column1 | H1: Temperature | I1: Humidity | J1: Occupancy Status | K1: HVAC Setting | L1: HVAC Category | M1: Energy Consumption | N1: EC | O1: z_zcore | P1: outlier | Q1: average | R1: Filled Energy Consumption | S1: Energy Category | T1: Tenant ID | U1: Occupancy | V1: Time Spent in Unit (Hours) | W1: Appliance Usage | X1: Energy Preferences
A2: 45422.982 | B2: =TEXT(sensor_data[[#This Row],[Timestamp]], "MMMM") -> May | C2: =IF(AND(HOUR(sensor_data[[#This Row],[Timestamp]])>=5, HOUR(sensor_data[[#This Row],[Timestamp]])<12), "Morning", IF(AND(HOUR(sensor_data[[#This Row],[Timestamp]])>=12, HOUR(sensor_data[[#This Row],[Timestamp]])<17), "Afternoon", IF(AND(HOUR(sensor_data[[#This Row],[Timestamp]])>=17, HOUR(sensor_data[[#This Row],[Timestamp]])<21), "Evening", "Night"))) -> Night | D2: =text([@Timestamp], "MMMM") | E2: =DAY(sensor_data[[#This Row],[Timestamp]]) -> 10 | F2: U327 | H2: 64.3 | I2: 40.2 | J2: FALSE | K2: 1 | L2: =IF(sensor_data[[#This Row],[HVAC Setting]]<=2, "Low", IF(sensor_data[[#This Row],[HVAC Setting]]=3, "Normal", "High")) -> Low | M2: 6 | N2: 6 | O2: =(sensor_data[[#This Row],[Energy Consumption]]-AVERAGE(sensor_data[Energy Consumption]))/_xlfn.STDEV.P(sensor_data[Energy Consumption]) -> -0.17909309 | P2: =IF(ABS(sensor_data[[#This Row],[z_zcore]])>3, "Outlier", "Normal") -> Normal | Q2: =AVERAGEIF(sensor_data[Unit ID], sensor_data[[#This Row],[Unit ID]], sensor_data[EC]) -> 18.586667 | R2: =IF(ISBLANK(sensor_data[[#This Row],[EC]]), sensor_data[[#This Row],[average]], sensor_data[[#This Row],[EC]]) -> 6 | S2: =IF(sensor_data[[#This Row],[Filled Energy Consumption]]>AVERAGE(sensor_data[Filled Energy Consumption]), "High", "Low") -> Low | T2: T158 | U2: FALSE | V2: 15 | W2: 1 | X2: warmer
A3: 45551.804 | B3: =TEXT(sensor_data[[#This Row],[Timestamp]], "MMMM") -> September | C3: =IF(AND(HOUR(sensor_data[[#This Row],[Timestamp]])>=5, HOUR(sensor_data[[#This Row],[Timestamp]])<12), "Morning", IF(AND(HOUR(sensor_data[[#This Row],[Timestamp]])>=12, HOUR(sensor_data[[#This Row],[Timestamp]])<17), "Afternoon", IF(AND(HOUR(sensor_data[[#This Row],[Timestamp]])>=17, HOUR(sensor_data[[#This Row],[Timestamp]])<21), "Evening", "Night"))) -> Evening | D3: =MONTH(sensor_data[[#This Row],[Timestamp]]) -> 9 | E3: =DAY(sensor_data[[#This Row],[Timestamp]]) -> 16 | F3: U327 | H3: 82.7 | I3: 37.9 | J3: TRUE | K3: 5 | L3: =IF(sensor_data[[#This Row],[HVAC Setting]]<=2, "Low", IF(sensor_data[[#This Row],[HVAC Setting]]=3, "Normal", "High")) -> High | M3: 30.17 | N3: 30.17 | O3: =(sensor_data[[#This Row],[Energy Consumption]]-AVERAGE(sensor_data[Energy Consumption]))/_xlfn.STDEV.P(sensor_data[Energy Consumption]) -> 0.10196336 | P3: =IF(ABS(sensor_data[[#This Row],[z_zcore]])>3, "Outlier", "Normal") -> Normal | Q3: =AVERAGEIF(sensor_data[Unit ID], sensor_data[[#This Row],[Unit ID]], sensor_data[EC]) -> 18.586667 | R3: =IF(ISBLANK(sensor_data[[#This Row],[EC]]), sensor_data[[#This Row],[average]], sensor_data[[#This Row],[EC]]) -> 30.17 | S3: =IF(sensor_data[[#This Row],[Filled Energy Consumption]]>AVERAGE(sensor_data[Filled Energy Consumption]), "High", "Low") -> High | T3: T273 | U3: TRUE | V3: 14 | W3: 1 | X3: warmer
A4: 45528.289 | B4: =TEXT(sensor_data[[#This Row],[Timestamp]], "MMMM") -> August | C4: =IF(AND(HOUR(sensor_data[[#This Row],[Timestamp]])>=5, HOUR(sensor_data[[#This Row],[Timestamp]])<12), "Morning", IF(AND(HOUR(sensor_data[[#This Row],[Timestamp]])>=12, HOUR(sensor_data[[#This Row],[Timestamp]])<17), "Afternoon", IF(AND(HOUR(sensor_data[[#This Row],[Timestamp]])>=17, HOUR(sensor_data[[#This Row],[Timestamp]])<21), "Evening", "Night"))) -> Morning | D4: =MONTH(sensor_data[[#This Row],[Timestamp]]) -> 8 | E4: =DAY(sensor_data[[#This Row],[Timestamp]]) -> 24 | F4: U327 | H4: 85.7 | I4: 61.1 | J4: TRUE | K4: 4.5 | L4: =IF(sensor_data[[#This Row],[HVAC Setting]]<=2, "Low", IF(sensor_data[[#This Row],[HVAC Setting]]=3, "Normal", "High")) -> High | M4: 28.36 | N4: 28.36 | O4: =(sensor_data[[#This Row],[Energy Consumption]]-AVERAGE(sensor_data[Energy Consumption]))/_xlfn.STDEV.P(sensor_data[Energy Consumption]) -> 0.080916103 | P4: =IF(ABS(sensor_data[[#This Row],[z_zcore]])>3, "Outlier", "Normal") -> Normal | Q4: =AVERAGEIF(sensor_data[Unit ID], sensor_data[[#This Row],[Unit ID]], sensor_data[EC]) -> 18.586667 | R4: =IF(ISBLANK(sensor_data[[#This Row],[EC]]), sensor_data[[#This Row],[average]], sensor_data[[#This Row],[EC]]) -> 28.36 | S4: =IF(sensor_data[[#This Row],[Filled Energy Consumption]]>AVERAGE(sensor_data[Filled Energy Consumption]), "High", "Low") -> High | T4: T258 | U4: TRUE | V4: 4 | W4: 1 | X4: cooler
A5: 45545.935 | B5: =TEXT(sensor_data[[#This Row],[Timestamp]], "MMMM") -> September | C5: =IF(AND(HOUR(sensor_data[[#This Row],[Timestamp]])>=5, HOUR(sensor_data[[#This Row],[Timestamp]])<12), "Morning", IF(AND(HOUR(sensor_data[[#This Row],[Timestamp]])>=12, HOUR(sensor_data[[#This Row],[Timestamp]])<17), "Afternoon", IF(AND(HOUR(sensor_data[[#This Row],[Timestamp]])>=17, HOUR(sensor_data[[#This Row],[Timestamp]])<21), "Evening", "Night"))) -> Night | D5: =MONTH(sensor_data[[#This Row],[Timestamp]]) -> 9 | E5: =DAY(sensor_data[[#This Row],[Timestamp]]) -> 10 | F5: U327 | H5: 61.2 | I5: 40.4 | J5: FALSE | K5: 2 | L5: =IF(sensor_data[[#This Row],[HVAC Setting]]<=2, "Low", IF(sensor_data[[#This Row],[HVAC Setting]]=3, "Normal", "High")) -> Low | M5: 10 | N5: 10 | O5: =(sensor_data[[#This Row],[Energy Consumption]]-AVERAGE(sensor_data[Energy Consumption]))/_xlfn.STDEV.P(sensor_data[Energy Consumption]) -> -0.13257982 | P5: =IF(ABS(sensor_data[[#This Row],[z_zcore]])>3, "Outlier", "Normal") -> Normal | Q5: =AVERAGEIF(sensor_data[Unit ID], sensor_data[[#This Row],[Unit ID]], sensor_data[EC]) -> 18.586667 | R5: =IF(ISBLANK(sensor_data[[#This Row],[EC]]), sensor_data[[#This Row],[average]], sensor_data[[#This Row],[EC]]) -> 10 | S5: =IF(sensor_data[[#This Row],[Filled Energy Consumption]]>AVERAGE(sensor_data[Filled Energy Consumption]), "High", "Low") -> Low | T5: T336 | U5: FALSE | V5: 22 | W5: 0 | X5: neutral
A6: 45582.715 | B6: =TEXT(sensor_data[[#This Row],[Timestamp]], "MMMM") -> October | C6: =IF(AND(HOUR(sensor_data[[#This Row],[Timestamp]])>=5, HOUR(sensor_data[[#This Row],[Timestamp]])<12), "Morning", IF(AND(HOUR(sensor_data[[#This Row],[Timestamp]])>=12, HOUR(sensor_data[[#This Row],[Timestamp]])<17), "Afternoon", IF(AND(HOUR(sensor_data[[#This Row],[Timestamp]])>=17, HOUR(sensor_data[[#This Row],[Timestamp]])<21), "Evening", "Night"))) -> Evening | D6: =MONTH(sensor_data[[#This Row],[Timestamp]]) -> 10 | E6: =DAY(sensor_data[[#This Row],[Timestamp]]) -> 17 | F6: U327 | H6: 66.9 | I6: 35.6 | J6: TRUE | K6: 5 | L6: =IF(sensor_data[[#This Row],[HVAC Setting]]<=2, "Low", IF(sensor_data[[#This Row],[HVAC Setting]]=3, "Normal", "High")) -> High | O6: =(sensor_data[[#This Row],[Energy Consumption]]-AVERAGE(sensor_data[Energy Consumption]))/_xlfn.STDEV.P(sensor_data[Energy Consumption]) -> -0.248863 | P6: =IF(ABS(sensor_data[[#This Row],[z_zcore]])>3, "Outlier", "Normal") -> Normal | Q6: =AVERAGEIF(sensor_data[Unit ID], sensor_data[[#This Row],[Unit ID]], sensor_data[EC]) -> 18.586667 | R6: =IF(ISBLANK(sensor_data[[#This Row],[EC]]), sensor_data[[#This Row],[average]], sensor_data[[#This Row],[EC]]) -> 18.586667 | S6: =IF(sensor_data[[#This Row],[Filled Energy Consumption]]>AVERAGE(sensor_data[Filled Energy Consumption]), "High", "Low") -> High | T6: T225 | U6: TRUE | V6: 19 | W6: 0 | X6: neutral
A7: 45525.895 | B7: =TEXT(sensor_data[[#This Row],[Timestamp]], "MMMM") -> August | C7: =IF(AND(HOUR(sensor_data[[#This Row],[Timestamp]])>=5, HOUR(sensor_data[[#This Row],[Timestamp]])<12), "Morning", IF(AND(HOUR(sensor_data[[#This Row],[Timestamp]])>=12, HOUR(sensor_data[[#This Row],[Timestamp]])<17), "Afternoon", IF(AND(HOUR(sensor_data[[#This Row],[Timestamp]])>=17, HOUR(sensor_data[[#This Row],[Timestamp]])<21), "Evening", "Night"))) -> Night | D7: =MONTH(sensor_data[[#This Row],[Timestamp]]) -> 8 | E7: =DAY(sensor_data[[#This Row],[Timestamp]]) -> 21 | F7: U327 | H7: 99.1 | I7: 69.9 | J7: TRUE | K7: 4 | L7: =IF(sensor_data[[#This Row],[HVAC Setting]]<=2, "Low", IF(sensor_data[[#This Row],[HVAC Setting]]=3, "Normal", "High")) -> High | M7: 23.5 | N7: 23.5 | O7: =(sensor_data[[#This Row],[Energy Consumption]]-AVERAGE(sensor_data[Energy Consumption]))/_xlfn.STDEV.P(sensor_data[Energy Consumption]) -> 0.024402478 | P7: =IF(ABS(sensor_data[[#This Row],[z_zcore]])>3, "Outlier", "Normal") -> Normal | Q7: =AVERAGEIF(sensor_data[Unit ID], sensor_data[[#This Row],[Unit ID]], sensor_data[EC]) -> 18.586667 | R7: =IF(ISBLANK(sensor_data[[#This Row],[EC]]), sensor_data[[#This Row],[average]], sensor_data[[#This Row],[EC]]) -> 23.5 | S7: =IF(sensor_data[[#This Row],[Filled Energy Consumption]]>AVERAGE(sensor_data[Filled Energy Consumption]), "High", "Low") -> High | T7: T150 | U7: TRUE | V7: 5 | W7: 1 | X7: warmer
A8: 45460.846 | B8: =TEXT(sensor_data[[#This Row],[Timestamp]], "MMMM") -> June | C8: =IF(AND(HOUR(sensor_data[[#This Row],[Timestamp]])>=5, HOUR(sensor_data[[#This Row],[Timestamp]])<12), "Morning", IF(AND(HOUR(sensor_data[[#This Row],[Timestamp]])>=12, HOUR(sensor_data[[#This Row],[Timestamp]])<17), "Afternoon", IF(AND(HOUR(sensor_data[[#This Row],[Timestamp]])>=17, HOUR(sensor_data[[#This Row],[Timestamp]])<21), "Evening", "Night"))) -> Evening | D8: =MONTH(sensor_data[[#This Row],[Timestamp]]) -> 6 | E8: =DAY(sensor_data[[#This Row],[Timestamp]]) -> 17 | F8: U327 | H8: 96.5 | I8: 56.6 | J8: TRUE | K8: 4 | L8: =IF(sensor_data[[#This Row],[HVAC Setting]]<=2, "Low", IF(sensor_data[[#This Row],[HVAC Setting]]=3, "Normal", "High")) -> High | M8: 26.2 | N8: 26.2 | O8: =(sensor_data[[#This Row],[Energy Consumption]]-AVERAGE(sensor_data[Energy Consumption]))/_xlfn.STDEV.P(sensor_data[Energy Consumption]) -> 0.055798936 | P8: =IF(ABS(sensor_data[[#This Row],[z_zcore]])>3, "Outlier", "Normal") -> Normal | Q8: =AVERAGEIF(sensor_data[Unit ID], sensor_data[[#This Row],[Unit ID]], sensor_data[EC]) -> 18.586667 | R8: =IF(ISBLANK(sensor_data[[#This Row],[EC]]), sensor_data[[#This Row],[average]], sensor_data[[#This Row],[EC]]) -> 26.2 | S8: =IF(sensor_data[[#This Row],[Filled Energy Consumption]]>AVERAGE(sensor_data[Filled Energy Consumption]), "High", "Low") -> High | T8: T216 | U8: TRUE | V8: 21 | W8: 1 | X8: neutral
A9: 45376.888 | B9: =TEXT(sensor_data[[#This Row],[Timestamp]], "MMMM") -> March | C9: =IF(AND(HOUR(sensor_data[[#This Row],[Timestamp]])>=5, HOUR(sensor_data[[#This Row],[Timestamp]])<12), "Morning", IF(AND(HOUR(sensor_data[[#This Row],[Timestamp]])>=12, HOUR(sensor_data[[#This Row],[Timestamp]])<17), "Afternoon", IF(AND(HOUR(sensor_data[[#This Row],[Timestamp]])>=17, HOUR(sensor_data[[#This Row],[Timestamp]])<21), "Evening", "Night"))) -> Night | D9: =MONTH(sensor_data[[#This Row],[Timestamp]]) -> 3 | E9: =DAY(sensor_data[[#This Row],[Timestamp]]) -> 25 | F9: U327 | H9: 68.1 | I9: 46.1 | J9: TRUE | K9: 3 | L9: =IF(sensor_data[[#This Row],[HVAC Setting]]<=2, "Low", IF(sensor_data[[#This Row],[HVAC Setting]]=3, "Normal", "High")) -> Normal | M9: 17.09 | N9: 17.09 | O9: =(sensor_data[[#This Row],[Energy Consumption]]-AVERAGE(sensor_data[Energy Consumption]))/_xlfn.STDEV.P(sensor_data[Energy Consumption]) -> -0.050135041 | P9: =IF(ABS(sensor_data[[#This Row],[z_zcore]])>3, "Outlier", "Normal") -> Normal | Q9: =AVERAGEIF(sensor_data[Unit ID], sensor_data[[#This Row],[Unit ID]], sensor_data[EC]) -> 18.586667 | R9: =IF(ISBLANK(sensor_data[[#This Row],[EC]]), sensor_data[[#This Row],[average]], sensor_data[[#This Row],[EC]]) -> 17.09 | S9: =IF(sensor_data[[#This Row],[Filled Energy Consumption]]>AVERAGE(sensor_data[Filled Energy Consumption]), "High", "Low") -> Low | T9: T139 | U9: TRUE | V9: 3 | W9: 1 | X9: warmer
A10: 45321.354 | B10: =TEXT(sensor_data[[#This Row],[Timestamp]], "MMMM") -> January | C10: =IF(AND(HOUR(sensor_data[[#This Row],[Timestamp]])>=5, HOUR(sensor_data[[#This Row],[Timestamp]])<12), "Morning", IF(AND(HOUR(sensor_data[[#This Row],[Timestamp]])>=12, HOUR(sensor_data[[#This Row],[Timestamp]])<17), "Afternoon", IF(AND(HOUR(sensor_data[[#This Row],[Timestamp]])>=17, HOUR(sensor_data[[#This Row],[Timestamp]])<21), "Evening", "Night"))) -> Morning | D10: =MONTH(sensor_data[[#This Row],[Timestamp]]) -> 1 | E10: =DAY(sensor_data[[#This Row],[Timestamp]]) -> 30 | F10: U327 | H10: 47.3 | I10: 37.4 | J10: FALSE | K10: 3 | L10: =IF(sensor_data[[#This Row],[HVAC Setting]]<=2, "Low", IF(sensor_data[[#This Row],[HVAC Setting]]=3, "Normal", "High")) -> Normal | O10: =(sensor_data[[#This Row],[Energy Consumption]]-AVERAGE(sensor_data[Energy Consumption]))/_xlfn.STDEV.P(sensor_data[Energy Consumption]) -> -0.248863 | P10: =IF(ABS(sensor_data[[#This Row],[z_zcore]])>3, "Outlier", "Normal") -> Normal | Q10: =AVERAGEIF(sensor_data[Unit ID], sensor_data[[#This Row],[Unit ID]], sensor_data[EC]) -> 18.586667 | R10: =IF(ISBLANK(sensor_data[[#This Row],[EC]]), sensor_data[[#This Row],[average]], sensor_data[[#This Row],[EC]]) -> 18.586667 | S10: =IF(sensor_data[[#This Row],[Filled Energy Consumption]]>AVERAGE(sensor_data[Filled Energy Consumption]), "High", "Low") -> High | T10: T150 | U10: FALSE | V10: 17 | W10: 0 | X10: warmer
A11: 45413.249 | B11: =TEXT(sensor_data[[#This Row],[Timestamp]], "MMMM") -> May | C11: =IF(AND(HOUR(sensor_data[[#This Row],[Timestamp]])>=5, HOUR(sensor_data[[#This Row],[Timestamp]])<12), "Morning", IF(AND(HOUR(sensor_data[[#This Row],[Timestamp]])>=12, HOUR(sensor_data[[#This Row],[Timestamp]])<17), "Afternoon", IF(AND(HOUR(sensor_data[[#This Row],[Timestamp]])>=17, HOUR(sensor_data[[#This Row],[Timestamp]])<21), "Evening", "Night"))) -> Morning | D11: =MONTH(sensor_data[[#This Row],[Timestamp]]) -> 5 | E11: =DAY(sensor_data[[#This Row],[Timestamp]]) -> 1 | F11: U327 | H11: 74.7 | I11: 32 | J11: FALSE | K11: 2 | L11: =IF(sensor_data[[#This Row],[HVAC Setting]]<=2, "Low", IF(sensor_data[[#This Row],[HVAC Setting]]=3, "Normal", "High")) -> Low | O11: =(sensor_data[[#This Row],[Energy Consumption]]-AVERAGE(sensor_data[Energy Consumption]))/_xlfn.STDEV.P(sensor_data[Energy Consumption]) -> -0.248863 | P11: =IF(ABS(sensor_data[[#This Row],[z_zcore]])>3, "Outlier", "Normal") -> Normal | Q11: =AVERAGEIF(sensor_data[Unit ID], sensor_data[[#This Row],[Unit ID]], sensor_data[EC]) -> 18.586667 | R11: =IF(ISBLANK(sensor_data[[#This Row],[EC]]), sensor_data[[#This Row],[average]], sensor_data[[#This Row],[EC]]) -> 18.586667 | S11: =IF(sensor_data[[#This Row],[Filled Energy Consumption]]>AVERAGE(sensor_data[Filled Energy Consumption]), "High", "Low") -> High | T11: T472 | U11: FALSE | V11: 22 | W11: 1 | X11: warmer
A12: 45629.446 | B12: =TEXT(sensor_data[[#This Row],[Timestamp]], "MMMM") -> December | C12: =IF(AND(HOUR(sensor_data[[#This Row],[Timestamp]])>=5, HOUR(sensor_data[[#This Row],[Timestamp]])<12), "Morning", IF(AND(HOUR(sensor_data[[#This Row],[Timestamp]])>=12, HOUR(sensor_data[[#This Row],[Timestamp]])<17), "Afternoon", IF(AND(HOUR(sensor_data[[#This Row],[Timestamp]])>=17, HOUR(sensor_data[[#This Row],[Timestamp]])<21), "Evening", "Night"))) -> Morning | D12: =MONTH(sensor_data[[#This Row],[Timestamp]]) -> 12 | E12: =DAY(sensor_data[[#This Row],[Timestamp]]) -> 3 | F12: U327 | H12: 57.6 | I12: 31.2 | J12: FALSE | K12: 4 | L12: =IF(sensor_data[[#This Row],[HVAC Setting]]<=2, "Low", IF(sensor_data[[#This Row],[HVAC Setting]]=3, "Normal", "High")) -> High | O12: =(sensor_data[[#This Row],[Energy Consumption]]-AVERAGE(sensor_data[Energy Consumption]))/_xlfn.STDEV.P(sensor_data[Energy Consumption]) -> -0.248863 | P12: =IF(ABS(sensor_data[[#This Row],[z_zcore]])>3, "Outlier", "Normal") -> Normal | Q12: =AVERAGEIF(sensor_data[Unit ID], sensor_data[[#This Row],[Unit ID]], sensor_data[EC]) -> 18.586667 | R12: =IF(ISBLANK(sensor_data[[#This Row],[EC]]), sensor_data[[#This Row],[average]], sensor_data[[#This Row],[EC]]) -> 18.586667 | S12: =IF(sensor_data[[#This Row],[Filled Energy Consumption]]>AVERAGE(sensor_data[Filled Energy Consumption]), "High", "Low") -> High | T12: T266 | U12: FALSE | V12: 14 | W12: 0 | X12: neutral
A13: 45425.521 | B13: =TEXT(sensor_data[[#This Row],[Timestamp]], "MMMM") -> May | C13: =IF(AND(HOUR(sensor_data[[#This Row],[Timestamp]])>=5, HOUR(sensor_data[[#This Row],[Timestamp]])<12), "Morning", IF(AND(HOUR(sensor_data[[#This Row],[Timestamp]])>=12, HOUR(sensor_data[[#This Row],[Timestamp]])<17), "Afternoon", IF(AND(HOUR(sensor_data[[#This Row],[Timestamp]])>=17, HOUR(sensor_data[[#This Row],[Timestamp]])<21), "Evening", "Night"))) -> Afternoon | D13: =MONTH(sensor_data[[#This Row],[Timestamp]]) -> 5 | E13: =DAY(sensor_data[[#This Row],[Timestamp]]) -> 13 | F13: U327 | H13: 65.8 | I13: 44.4 | J13: TRUE | K13: 2 | L13: =IF(sensor_data[[#This Row],[HVAC Setting]]<=2, "Low", IF(sensor_data[[#This Row],[HVAC Setting]]=3, "Normal", "High")) -> Low | M13: 13.02 | N13: 13.02 | O13: =(sensor_data[[#This Row],[Energy Consumption]]-AVERAGE(sensor_data[Energy Consumption]))/_xlfn.STDEV.P(sensor_data[Energy Consumption]) -> -0.097462295 | P13: =IF(ABS(sensor_data[[#This Row],[z_zcore]])>3, "Outlier", "Normal") -> Normal | Q13: =AVERAGEIF(sensor_data[Unit ID], sensor_data[[#This Row],[Unit ID]], sensor_data[EC]) -> 18.586667 | R13: =IF(ISBLANK(sensor_data[[#This Row],[EC]]), sensor_data[[#This Row],[average]], sensor_data[[#This Row],[EC]]) -> 13.02 | S13: =IF(sensor_data[[#This Row],[Filled Energy Consumption]]>AVERAGE(sensor_data[Filled Energy Consumption]), "High", "Low") -> Low | T13: T368 | U13: TRUE | V13: 11 | W13: 1 | X13: cooler
A14: 45623.234 | B14: =TEXT(sensor_data[[#This Row],[Timestamp]], "MMMM") -> November | C14: =IF(AND(HOUR(sensor_data[[#This Row],[Timestamp]])>=5, HOUR(sensor_data[[#This Row],[Timestamp]])<12), "Morning", IF(AND(HOUR(sensor_data[[#This Row],[Timestamp]])>=12, HOUR(sensor_data[[#This Row],[Timestamp]])<17), "Afternoon", IF(AND(HOUR(sensor_data[[#This Row],[Timestamp]])>=17, HOUR(sensor_data[[#This Row],[Timestamp]])<21), "Evening", "Night"))) -> Morning | D14: =MONTH(sensor_data[[#This Row],[Timestamp]]) -> 11 | E14: =DAY(sensor_data[[#This Row],[Timestamp]]) -> 27 | F14: U327 | H14: 63.7 | I14: 53 | J14: FALSE | K14: 2 | L14: =IF(sensor_data[[#This Row],[HVAC Setting]]<=2, "Low", IF(sensor_data[[#This Row],[HVAC Setting]]=3, "Normal", "High")) -> Low | M14: 10 | N14: 10 | O14: =(sensor_data[[#This Row],[Energy Consumption]]-AVERAGE(sensor_data[Energy Consumption]))/_xlfn.STDEV.P(sensor_data[Energy Consumption]) -> -0.13257982 | P14: =IF(ABS(sensor_data[[#This Row],[z_zcore]])>3, "Outlier", "Normal") -> Normal | Q14: =AVERAGEIF(sensor_data[Unit ID], sensor_data[[#This Row],[Unit ID]], sensor_data[EC]) -> 18.586667 | R14: =IF(ISBLANK(sensor_data[[#This Row],[EC]]), sensor_data[[#This Row],[average]], sensor_data[[#This Row],[EC]]) -> 10 | S14: =IF(sensor_data[[#This Row],[Filled Energy Consumption]]>AVERAGE(sensor_data[Filled Energy Consumption]), "High", "Low") -> Low | T14: T446 | U14: FALSE | V14: 11 | W14: 0 | X14: warmer
A15: 45426.301 | B15: =TEXT(sensor_data[[#This Row],[Timestamp]], "MMMM") -> May | C15: =IF(AND(HOUR(sensor_data[[#This Row],[Timestamp]])>=5, HOUR(sensor_data[[#This Row],[Timestamp]])<12), "Morning", IF(AND(HOUR(sensor_data[[#This Row],[Timestamp]])>=12, HOUR(sensor_data[[#This Row],[Timestamp]])<17), "Afternoon", IF(AND(HOUR(sensor_data[[#This Row],[Timestamp]])>=17, HOUR(sensor_data[[#This Row],[Timestamp]])<21), "Evening", "Night"))) -> Morning | D15: =MONTH(sensor_data[[#This Row],[Timestamp]]) -> 5 | E15: =DAY(sensor_data[[#This Row],[Timestamp]]) -> 14 | F15: U327 | H15: 77.6 | I15: 55 | J15: TRUE | K15: 4 | L15: =IF(sensor_data[[#This Row],[HVAC Setting]]<=2, "Low", IF(sensor_data[[#This Row],[HVAC Setting]]=3, "Normal", "High")) -> High | M15: 22.93 | N15: 22.93 | O15: =(sensor_data[[#This Row],[Energy Consumption]]-AVERAGE(sensor_data[Energy Consumption]))/_xlfn.STDEV.P(sensor_data[Energy Consumption]) -> 0.017774336 | P15: =IF(ABS(sensor_data[[#This Row],[z_zcore]])>3, "Outlier", "Normal") -> Normal | Q15: =AVERAGEIF(sensor_data[Unit ID], sensor_data[[#This Row],[Unit ID]], sensor_data[EC]) -> 18.586667 | R15: =IF(ISBLANK(sensor_data[[#This Row],[EC]]), sensor_data[[#This Row],[average]], sensor_data[[#This Row],[EC]]) -> 22.93 | S15: =IF(sensor_data[[#This Row],[Filled Energy Consumption]]>AVERAGE(sensor_data[Filled Energy Consumption]), "High", "Low") -> High | T15: T166 | U15: TRUE | V15: 23 | W15: 1 | X15: warmer
A16: 45478.39 | B16: =TEXT(sensor_data[[#This Row],[Timestamp]], "MMMM") -> July | C16: =IF(AND(HOUR(sensor_data[[#This Row],[Timestamp]])>=5, HOUR(sensor_data[[#This Row],[Timestamp]])<12), "Morning", IF(AND(HOUR(sensor_data[[#This Row],[Timestamp]])>=12, HOUR(sensor_data[[#This Row],[Timestamp]])<17), "Afternoon", IF(AND(HOUR(sensor_data[[#This Row],[Timestamp]])>=17, HOUR(sensor_data[[#This Row],[Timestamp]])<21), "Evening", "Night"))) -> Morning | D16: =MONTH(sensor_data[[#This Row],[Timestamp]]) -> 7 | E16: =DAY(sensor_data[[#This Row],[Timestamp]]) -> 5 | F16: U327 | H16: 98.9 | I16: 49.2 | J16: TRUE | K16: 5 | L16: =IF(sensor_data[[#This Row],[HVAC Setting]]<=2, "Low", IF(sensor_data[[#This Row],[HVAC Setting]]=3, "Normal", "High")) -> High | M16: 29.62 | N16: 29.62 | O16: =(sensor_data[[#This Row],[Energy Consumption]]-AVERAGE(sensor_data[Energy Consumption]))/_xlfn.STDEV.P(sensor_data[Energy Consumption]) -> 0.095567784 | P16: =IF(ABS(sensor_data[[#This Row],[z_zcore]])>3, "Outlier", "Normal") -> Normal | Q16: =AVERAGEIF(sensor_data[Unit ID], sensor_data[[#This Row],[Unit ID]], sensor_data[EC]) -> 18.586667 | R16: =IF(ISBLANK(sensor_data[[#This Row],[EC]]), sensor_data[[#This Row],[average]], sensor_data[[#This Row],[EC]]) -> 29.62 | S16: =IF(sensor_data[[#This Row],[Filled Energy Consumption]]>AVERAGE(sensor_data[Filled Energy Consumption]), "High", "Low") -> High | T16: T224 | U16: TRUE | V16: 24 | W16: 0 | X16: warmer
A17: 45608.311 | B17: =TEXT(sensor_data[[#This Row],[Timestamp]], "MMMM") -> November | C17: =IF(AND(HOUR(sensor_data[[#This Row],[Timestamp]])>=5, HOUR(sensor_data[[#This Row],[Timestamp]])<12), "Morning", IF(AND(HOUR(sensor_data[[#This Row],[Timestamp]])>=12, HOUR(sensor_data[[#This Row],[Timestamp]])<17), "Afternoon", IF(AND(HOUR(sensor_data[[#This Row],[Timestamp]])>=17, HOUR(sensor_data[[#This Row],[Timestamp]])<21), "Evening", "Night"))) -> Morning | D17: =MONTH(sensor_data[[#This Row],[Timestamp]]) -> 11 | E17: =DAY(sensor_data[[#This Row],[Timestamp]]) -> 12 | F17: U327 | H17: 69.8 | I17: 45.6 | J17: TRUE | K17: 2 | L17: =IF(sensor_data[[#This Row],[HVAC Setting]]<=2, "Low", IF(sensor_data[[#This Row],[HVAC Setting]]=3, "Normal", "High")) -> Low | M17: 12.78 | N17: 12.78 | O17: =(sensor_data[[#This Row],[Energy Consumption]]-AVERAGE(sensor_data[Energy Consumption]))/_xlfn.STDEV.P(sensor_data[Energy Consumption]) -> -0.10025309 | P17: =IF(ABS(sensor_data[[#This Row],[z_zcore]])>3, "Outlier", "Normal") -> Normal | Q17: =AVERAGEIF(sensor_data[Unit ID], sensor_data[[#This Row],[Unit ID]], sensor_data[EC]) -> 18.586667 | R17: =IF(ISBLANK(sensor_data[[#This Row],[EC]]), sensor_data[[#This Row],[average]], sensor_data[[#This Row],[EC]]) -> 12.78 | S17: =IF(sensor_data[[#This Row],[Filled Energy Consumption]]>AVERAGE(sensor_data[Filled Energy Consumption]), "High", "Low") -> Low | T17: T423 | U17: TRUE | V17: 22 | W17: 1 | X17: warmer
A18: 45558.673 | B18: =TEXT(sensor_data[[#This Row],[Timestamp]], "MMMM") -> September | C18: =IF(AND(HOUR(sensor_data[[#This Row],[Timestamp]])>=5, HOUR(sensor_data[[#This Row],[Timestamp]])<12), "Morning", IF(AND(HOUR(sensor_data[[#This Row],[Timestamp]])>=12, HOUR(sensor_data[[#This Row],[Timestamp]])<17), "Afternoon", IF(AND(HOUR(sensor_data[[#This Row],[Timestamp]])>=17, HOUR(sensor_data[[#This Row],[Timestamp]])<21), "Evening", "Night"))) -> Afternoon | D18: =MONTH(sensor_data[[#This Row],[Timestamp]]) -> 9 | E18: =DAY(sensor_data[[#This Row],[Timestamp]]) -> 23 | F18: U327 | H18: 60.8 | I18: 43.2 | J18: FALSE | K18: 2 | L18: =IF(sensor_data[[#This Row],[HVAC Setting]]<=2, "Low", IF(sensor_data[[#This Row],[HVAC Setting]]=3, "Normal", "High")) -> Low | O18: =(sensor_data[[#This Row],[Energy Consumption]]-AVERAGE(sensor_data[Energy Consumption]))/_xlfn.STDEV.P(sensor_data[Energy Consumption]) -> -0.248863 | P18: =IF(ABS(sensor_data[[#This Row],[z_zcore]])>3, "Outlier", "Normal") -> Normal | Q18: =AVERAGEIF(sensor_data[Unit ID], sensor_data[[#This Row],[Unit ID]], sensor_data[EC]) -> 18.586667 | R18: =IF(ISBLANK(sensor_data[[#This Row],[EC]]), sensor_data[[#This Row],[average]], sensor_data[[#This Row],[EC]]) -> 18.586667 | S18: =IF(sensor_data[[#This Row],[Filled Energy Consumption]]>AVERAGE(sensor_data[Filled Energy Consumption]), "High", "Low") -> High | T18: T073 | U18: FALSE | V18: 15 | W18: 0 | X18: warmer
A19: 45579.236 | B19: =TEXT(sensor_data[[#This Row],[Timestamp]], "MMMM") -> October | C19: =IF(AND(HOUR(sensor_data[[#This Row],[Timestamp]])>=5, HOUR(sensor_data[[#This Row],[Timestamp]])<12), "Morning", IF(AND(HOUR(sensor_data[[#This Row],[Timestamp]])>=12, HOUR(sensor_data[[#This Row],[Timestamp]])<17), "Afternoon", IF(AND(HOUR(sensor_data[[#This Row],[Timestamp]])>=17, HOUR(sensor_data[[#This Row],[Timestamp]])<21), "Evening", "Night"))) -> Morning | D19: =MONTH(sensor_data[[#This Row],[Timestamp]]) -> 10 | E19: =DAY(sensor_data[[#This Row],[Timestamp]]) -> 14 | F19: U327 | H19: 61.8 | I19: 52.3 | J19: FALSE | K19: 0 | L19: =IF(sensor_data[[#This Row],[HVAC Setting]]<=2, "Low", IF(sensor_data[[#This Row],[HVAC Setting]]=3, "Normal", "High")) -> Low | M19: 1 | N19: 1 | O19: =(sensor_data[[#This Row],[Energy Consumption]]-AVERAGE(sensor_data[Energy Consumption]))/_xlfn.STDEV.P(sensor_data[Energy Consumption]) -> -0.23723468 | P19: =IF(ABS(sensor_data[[#This Row],[z_zcore]])>3, "Outlier", "Normal") -> Normal | Q19: =AVERAGEIF(sensor_data[Unit ID], sensor_data[[#This Row],[Unit ID]], sensor_data[EC]) -> 18.586667 | R19: =IF(ISBLANK(sensor_data[[#This Row],[EC]]), sensor_data[[#This Row],[average]], sensor_data[[#This Row],[EC]]) -> 1 | S19: =IF(sensor_data[[#This Row],[Filled Energy Consumption]]>AVERAGE(sensor_data[Filled Energy Consumption]), "High", "Low") -> Low | T19: T326 | U19: FALSE | V19: 6 | W19: 0 | X19: cooler
A20: 45483.753 | B20: =TEXT(sensor_data[[#This Row],[Timestamp]], "MMMM") -> July | C20: =IF(AND(HOUR(sensor_data[[#This Row],[Timestamp]])>=5, HOUR(sensor_data[[#This Row],[Timestamp]])<12), "Morning", IF(AND(HOUR(sensor_data[[#This Row],[Timestamp]])>=12, HOUR(sensor_data[[#This Row],[Timestamp]])<17), "Afternoon", IF(AND(HOUR(sensor_data[[#This Row],[Timestamp]])>=17, HOUR(sensor_data[[#This Row],[Timestamp]])<21), "Evening", "Night"))) -> Evening | D20: =MONTH(sensor_data[[#This Row],[Timestamp]]) -> 7 | E20: =DAY(sensor_data[[#This Row],[Timestamp]]) -> 10 | F20: U327 | H20: 85.1 | I20: 63.1 | J20: TRUE | K20: 4 | L20: =IF(sensor_data[[#This Row],[HVAC Setting]]<=2, "Low", IF(sensor_data[[#This Row],[HVAC Setting]]=3, "Normal", "High")) -> High | M20: 26.81 | N20: 26.81 | O20: =(sensor_data[[#This Row],[Energy Consumption]]-AVERAGE(sensor_data[Energy Consumption]))/_xlfn.STDEV.P(sensor_data[Energy Consumption]) -> 0.06289221 | P20: =IF(ABS(sensor_data[[#This Row],[z_zcore]])>3, "Outlier", "Normal") -> Normal | Q20: =AVERAGEIF(sensor_data[Unit ID], sensor_data[[#This Row],[Unit ID]], sensor_data[EC]) -> 18.586667 | R20: =IF(ISBLANK(sensor_data[[#This Row],[EC]]), sensor_data[[#This Row],[average]], sensor_data[[#This Row],[EC]]) -> 26.81 | S20: =IF(sensor_data[[#This Row],[Filled Energy Consumption]]>AVERAGE(sensor_data[Filled Energy Consumption]), "High", "Low") -> High | T20: T183 | U20: TRUE | V20: 21 | W20: 1 | X20: neutral
A21: 45626.363 | B21: =TEXT(sensor_data[[#This Row],[Timestamp]], "MMMM") -> November | C21: =IF(AND(HOUR(sensor_data[[#This Row],[Timestamp]])>=5, HOUR(sensor_data[[#This Row],[Timestamp]])<12), "Morning", IF(AND(HOUR(sensor_data[[#This Row],[Timestamp]])>=12, HOUR(sensor_data[[#This Row],[Timestamp]])<17), "Afternoon", IF(AND(HOUR(sensor_data[[#This Row],[Timestamp]])>=17, HOUR(sensor_data[[#This Row],[Timestamp]])<21), "Evening", "Night"))) -> Morning | D21: =MONTH(sensor_data[[#This Row],[Timestamp]]) -> 11 | E21: =DAY(sensor_data[[#This Row],[Timestamp]]) -> 30 | F21: U327 | H21: 71.6 | I21: 43.8 | J21: TRUE | K21: 3.5 | L21: =IF(sensor_data[[#This Row],[HVAC Setting]]<=2, "Low", IF(sensor_data[[#This Row],[HVAC Setting]]=3, "Normal", "High")) -> High | M21: 21.32 | N21: 21.32 | O21: =(sensor_data[[#This Row],[Energy Consumption]]-AVERAGE(sensor_data[Energy Consumption]))/_xlfn.STDEV.P(sensor_data[Energy Consumption]) -> -0.00094725571 | P21: =IF(ABS(sensor_data[[#This Row],[z_zcore]])>3, "Outlier", "Normal") -> Normal | Q21: =AVERAGEIF(sensor_data[Unit ID], sensor_data[[#This Row],[Unit ID]], sensor_data[EC]) -> 18.586667 | R21: =IF(ISBLANK(sensor_data[[#This Row],[EC]]), sensor_data[[#This Row],[average]], sensor_data[[#This Row],[EC]]) -> 21.32 | S21: =IF(sensor_data[[#This Row],[Filled Energy Consumption]]>AVERAGE(sensor_data[Filled Energy Consumption]), "High", "Low") -> High | T21: T263 | U21: TRUE | V21: 11 | W21: 1 | X21: warmer
A22: 45358.25 | B22: =TEXT(sensor_data[[#This Row],[Timestamp]], "MMMM") -> March | C22: =IF(AND(HOUR(sensor_data[[#This Row],[Timestamp]])>=5, HOUR(sensor_data[[#This Row],[Timestamp]])<12), "Morning", IF(AND(HOUR(sensor_data[[#This Row],[Timestamp]])>=12, HOUR(sensor_data[[#This Row],[Timestamp]])<17), "Afternoon", IF(AND(HOUR(sensor_data[[#This Row],[Timestamp]])>=17, HOUR(sensor_data[[#This Row],[Timestamp]])<21), "Evening", "Night"))) -> Morning | D22: =MONTH(sensor_data[[#This Row],[Timestamp]]) -> 3 | E22: =DAY(sensor_data[[#This Row],[Timestamp]]) -> 7 | F22: U323 | H22: 71.1 | I22: 35 | J22: FALSE | K22: 1 | L22: =IF(sensor_data[[#This Row],[HVAC Setting]]<=2, "Low", IF(sensor_data[[#This Row],[HVAC Setting]]=3, "Normal", "High")) -> Low | M22: 5 | N22: 5 | O22: =(sensor_data[[#This Row],[Energy Consumption]]-AVERAGE(sensor_data[Energy Consumption]))/_xlfn.STDEV.P(sensor_data[Energy Consumption]) -> -0.19072141 | P22: =IF(ABS(sensor_data[[#This Row],[z_zcore]])>3, "Outlier", "Normal") -> Normal | Q22: =AVERAGEIF(sensor_data[Unit ID], sensor_data[[#This Row],[Unit ID]], sensor_data[EC]) -> 18.5915 | R22: =IF(ISBLANK(sensor_data[[#This Row],[EC]]), sensor_data[[#This Row],[average]], sensor_data[[#This Row],[EC]]) -> 5 | S22: =IF(sensor_data[[#This Row],[Filled Energy Consumption]]>AVERAGE(sensor_data[Filled Energy Consumption]), "High", "Low") -> Low | T22: T443 | U22: FALSE | V22: 15 | W22: 0 | X22: neutral
A23: 45309.094 | B23: =TEXT(sensor_data[[#This Row],[Timestamp]], "MMMM") -> January | C23: =IF(AND(HOUR(sensor_data[[#This Row],[Timestamp]])>=5, HOUR(sensor_data[[#This Row],[Timestamp]])<12), "Morning", IF(AND(HOUR(sensor_data[[#This Row],[Timestamp]])>=12, HOUR(sensor_data[[#This Row],[Timestamp]])<17), "Afternoon", IF(AND(HOUR(sensor_data[[#This Row],[Timestamp]])>=17, HOUR(sensor_data[[#This Row],[Timestamp]])<21), "Evening", "Night"))) -> Night | D23: =MONTH(sensor_data[[#This Row],[Timestamp]]) -> 1 | E23: =DAY(sensor_data[[#This Row],[Timestamp]]) -> 18 | F23: U323 | H23: 35 | I23: 27.6 | J23: FALSE | K23: 1 | L23: =IF(sensor_data[[#This Row],[HVAC Setting]]<=2, "Low", IF(sensor_data[[#This Row],[HVAC Setting]]=3, "Normal", "High")) -> Low | M23: 8 | N23: 8 | O23: =(sensor_data[[#This Row],[Energy Consumption]]-AVERAGE(sensor_data[Energy Consumption]))/_xlfn.STDEV.P(sensor_data[Energy Consumption]) -> -0.15583645 | P23: =IF(ABS(sensor_data[[#This Row],[z_zcore]])>3, "Outlier", "Normal") -> Normal | Q23: =AVERAGEIF(sensor_data[Unit ID], sensor_data[[#This Row],[Unit ID]], sensor_data[EC]) -> 18.5915 | R23: =IF(ISBLANK(sensor_data[[#This Row],[EC]]), sensor_data[[#This Row],[average]], sensor_data[[#This Row],[EC]]) -> 8 | S23: =IF(sensor_data[[#This Row],[Filled Energy Consumption]]>AVERAGE(sensor_data[Filled Energy Consumption]), "High", "Low") -> Low | T23: T195 | U23: FALSE | V23: 14 | W23: 0 | X23: neutral
A24: 45333.693 | B24: =TEXT(sensor_data[[#This Row],[Timestamp]], "MMMM") -> February | C24: =IF(AND(HOUR(sensor_data[[#This Row],[Timestamp]])>=5, HOUR(sensor_data[[#This Row],[Timestamp]])<12), "Morning", IF(AND(HOUR(sensor_data[[#This Row],[Timestamp]])>=12, HOUR(sensor_data[[#This Row],[Timestamp]])<17), "Afternoon", IF(AND(HOUR(sensor_data[[#This Row],[Timestamp]])>=17, HOUR(sensor_data[[#This Row],[Timestamp]])<21), "Evening", "Night"))) -> Afternoon | D24: =MONTH(sensor_data[[#This Row],[Timestamp]]) -> 2 | E24: =DAY(sensor_data[[#This Row],[Timestamp]]) -> 11 | F24: U323 | H24: 58.9 | I24: 30.4 | J24: FALSE | K24: 4.5 | L24: =IF(sensor_data[[#This Row],[HVAC Setting]]<=2, "Low", IF(sensor_data[[#This Row],[HVAC Setting]]=3, "Normal", "High")) -> High | M24: 23.62 | N24: 23.62 | O24: =(sensor_data[[#This Row],[Energy Consumption]]-AVERAGE(sensor_data[Energy Consumption]))/_xlfn.STDEV.P(sensor_data[Energy Consumption]) -> 0.025797876 | P24: =IF(ABS(sensor_data[[#This Row],[z_zcore]])>3, "Outlier", "Normal") -> Normal | Q24: =AVERAGEIF(sensor_data[Unit ID], sensor_data[[#This Row],[Unit ID]], sensor_data[EC]) -> 18.5915 | R24: =IF(ISBLANK(sensor_data[[#This Row],[EC]]), sensor_data[[#This Row],[average]], sensor_data[[#This Row],[EC]]) -> 23.62 | S24: =IF(sensor_data[[#This Row],[Filled Energy Consumption]]>AVERAGE(sensor_data[Filled Energy Consumption]), "High", "Low") -> High | T24: T266 | U24: FALSE | V24: 9 | W24: 0 | X24: cooler
A25: 45513.76 | B25: =TEXT(sensor_data[[#This Row],[Timestamp]], "MMMM") -> August | C25: =IF(AND(HOUR(sensor_data[[#This Row],[Timestamp]])>=5, HOUR(sensor_data[[#This Row],[Timestamp]])<12), "Morning", IF(AND(HOUR(sensor_data[[#This Row],[Timestamp]])>=12, HOUR(sensor_data[[#This Row],[Timestamp]])<17), "Afternoon", IF(AND(HOUR(sensor_data[[#This Row],[Timestamp]])>=17, HOUR(sensor_data[[#This Row],[Timestamp]])<21), "Evening", "Night"))) -> Evening | D25: =MONTH(sensor_data[[#This Row],[Timestamp]]) -> 8 | E25: =DAY(sensor_data[[#This Row],[Timestamp]]) -> 9 | F25: U323 | H25: 95.4 | I25: 58.7 | J25: FALSE | K25: 4 | L25: =IF(sensor_data[[#This Row],[HVAC Setting]]<=2, "Low", IF(sensor_data[[#This Row],[HVAC Setting]]=3, "Normal", "High")) -> High | M25: 24.2 | N25: 24.2 | O25: =(sensor_data[[#This Row],[Energy Consumption]]-AVERAGE(sensor_data[Energy Consumption]))/_xlfn.STDEV.P(sensor_data[Energy Consumption]) -> 0.0325423 | P25: =IF(ABS(sensor_data[[#This Row],[z_zcore]])>3, "Outlier", "Normal") -> Normal | Q25: =AVERAGEIF(sensor_data[Unit ID], sensor_data[[#This Row],[Unit ID]], sensor_data[EC]) -> 18.5915 | R25: =IF(ISBLANK(sensor_data[[#This Row],[EC]]), sensor_data[[#This Row],[average]], sensor_data[[#This Row],[EC]]) -> 24.2 | S25: =IF(sensor_data[[#This Row],[Filled Energy Consumption]]>AVERAGE(sensor_data[Filled Energy Consumption]), "High", "Low") -> High | T25: T280 | U25: FALSE | V25: 22 | W25: 1 | X25: cooler
A26: 45538.723 | B26: =TEXT(sensor_data[[#This Row],[Timestamp]], "MMMM") -> September | C26: =IF(AND(HOUR(sensor_data[[#This Row],[Timestamp]])>=5, HOUR(sensor_data[[#This Row],[Timestamp]])<12), "Morning", IF(AND(HOUR(sensor_data[[#This Row],[Timestamp]])>=12, HOUR(sensor_data[[#This Row],[Timestamp]])<17), "Afternoon", IF(AND(HOUR(sensor_data[[#This Row],[Timestamp]])>=17, HOUR(sensor_data[[#This Row],[Timestamp]])<21), "Evening", "Night"))) -> Evening | D26: =MONTH(sensor_data[[#This Row],[Timestamp]]) -> 9 | E26: =DAY(sensor_data[[#This Row],[Timestamp]]) -> 3 | F26: U323 | H26: 67.6 | I26: 31.2 | J26: TRUE | K26: 3 | L26: =IF(sensor_data[[#This Row],[HVAC Setting]]<=2, "Low", IF(sensor_data[[#This Row],[HVAC Setting]]=3, "Normal", "High")) -> Normal | M26: 19.1 | N26: 19.1 | O26: =(sensor_data[[#This Row],[Energy Consumption]]-AVERAGE(sensor_data[Energy Consumption]))/_xlfn.STDEV.P(sensor_data[Energy Consumption]) -> -0.026762122 | P26: =IF(ABS(sensor_data[[#This Row],[z_zcore]])>3, "Outlier", "Normal") -> Normal | Q26: =AVERAGEIF(sensor_data[Unit ID], sensor_data[[#This Row],[Unit ID]], sensor_data[EC]) -> 18.5915 | R26: =IF(ISBLANK(sensor_data[[#This Row],[EC]]), sensor_data[[#This Row],[average]], sensor_data[[#This Row],[EC]]) -> 19.1 | S26: =IF(sensor_data[[#This Row],[Filled Energy Consumption]]>AVERAGE(sensor_data[Filled Energy Consumption]), "High", "Low") -> High | T26: T246 | U26: TRUE | V26: 5 | W26: 1 | X26: warmer
A27: 45344.949 | B27: =TEXT(sensor_data[[#This Row],[Timestamp]], "MMMM") -> February | C27: =IF(AND(HOUR(sensor_data[[#This Row],[Timestamp]])>=5, HOUR(sensor_data[[#This Row],[Timestamp]])<12), "Morning", IF(AND(HOUR(sensor_data[[#This Row],[Timestamp]])>=12, HOUR(sensor_data[[#This Row],[Timestamp]])<17), "Afternoon", IF(AND(HOUR(sensor_data[[#This Row],[Timestamp]])>=17, HOUR(sensor_data[[#This Row],[Timestamp]])<21), "Evening", "Night"))) -> Night | D27: =MONTH(sensor_data[[#This Row],[Timestamp]]) -> 2 | E27: =DAY(sensor_data[[#This Row],[Timestamp]]) -> 22 | F27: U323 | H27: 35.3 | I27: 36.9 | J27: FALSE | K27: 2 | L27: =IF(sensor_data[[#This Row],[HVAC Setting]]<=2, "Low", IF(sensor_data[[#This Row],[HVAC Setting]]=3, "Normal", "High")) -> Low | M27: 13 | N27: 13 | O27: =(sensor_data[[#This Row],[Energy Consumption]]-AVERAGE(sensor_data[Energy Consumption]))/_xlfn.STDEV.P(sensor_data[Energy Consumption]) -> -0.097694862 | P27: =IF(ABS(sensor_data[[#This Row],[z_zcore]])>3, "Outlier", "Normal") -> Normal | Q27: =AVERAGEIF(sensor_data[Unit ID], sensor_data[[#This Row],[Unit ID]], sensor_data[EC]) -> 18.5915 | R27: =IF(ISBLANK(sensor_data[[#This Row],[EC]]), sensor_data[[#This Row],[average]], sensor_data[[#This Row],[EC]]) -> 13 | S27: =IF(sensor_data[[#This Row],[Filled Energy Consumption]]>AVERAGE(sensor_data[Filled Energy Consumption]), "High", "Low") -> Low | T27: T031 | U27: FALSE | V27: 20 | W27: 1 | X27: neutral
A28: 45586.976 | B28: =TEXT(sensor_data[[#This Row],[Timestamp]], "MMMM") -> October | C28: =IF(AND(HOUR(sensor_data[[#This Row],[Timestamp]])>=5, HOUR(sensor_data[[#This Row],[Timestamp]])<12), "Morning", IF(AND(HOUR(sensor_data[[#This Row],[Timestamp]])>=12, HOUR(sensor_data[[#This Row],[Timestamp]])<17), "Afternoon", IF(AND(HOUR(sensor_data[[#This Row],[Timestamp]])>=17, HOUR(sensor_data[[#This Row],[Timestamp]])<21), "Evening", "Night"))) -> Night | D28: =MONTH(sensor_data[[#This Row],[Timestamp]]) -> 10 | E28: =DAY(sensor_data[[#This Row],[Timestamp]]) -> 21 | F28: U323 | H28: 74.6 | I28: 47.7 | J28: FALSE | K28: 2 | L28: =IF(sensor_data[[#This Row],[HVAC Setting]]<=2, "Low", IF(sensor_data[[#This Row],[HVAC Setting]]=3, "Normal", "High")) -> Low | M28: 10 | N28: 10 | O28: =(sensor_data[[#This Row],[Energy Consumption]]-AVERAGE(sensor_data[Energy Consumption]))/_xlfn.STDEV.P(sensor_data[Energy Consumption]) -> -0.13257982 | P28: =IF(ABS(sensor_data[[#This Row],[z_zcore]])>3, "Outlier", "Normal") -> Normal | Q28: =AVERAGEIF(sensor_data[Unit ID], sensor_data[[#This Row],[Unit ID]], sensor_data[EC]) -> 18.5915 | R28: =IF(ISBLANK(sensor_data[[#This Row],[EC]]), sensor_data[[#This Row],[average]], sensor_data[[#This Row],[EC]]) -> 10 | S28: =IF(sensor_data[[#This Row],[Filled Energy Consumption]]>AVERAGE(sensor_data[Filled Energy Consumption]), "High", "Low") -> Low | T28: T498 | U28: FALSE | V28: 11 | W28: 0 | X28: warmer
A29: 45378.107 | B29: =TEXT(sensor_data[[#This Row],[Timestamp]], "MMMM") -> March | C29: =IF(AND(HOUR(sensor_data[[#This Row],[Timestamp]])>=5, HOUR(sensor_data[[#This Row],[Timestamp]])<12), "Morning", IF(AND(HOUR(sensor_data[[#This Row],[Timestamp]])>=12, HOUR(sensor_data[[#This Row],[Timestamp]])<17), "Afternoon", IF(AND(HOUR(sensor_data[[#This Row],[Timestamp]])>=17, HOUR(sensor_data[[#This Row],[Timestamp]])<21), "Evening", "Night"))) -> Night | D29: =MONTH(sensor_data[[#This Row],[Timestamp]]) -> 3 | E29: =DAY(sensor_data[[#This Row],[Timestamp]]) -> 27 | F29: U323 | H29: 74.1 | I29: 49.6 | J29: FALSE | K29: 1 | L29: =IF(sensor_data[[#This Row],[HVAC Setting]]<=2, "Low", IF(sensor_data[[#This Row],[HVAC Setting]]=3, "Normal", "High")) -> Low | M29: 5 | N29: 5 | O29: =(sensor_data[[#This Row],[Energy Consumption]]-AVERAGE(sensor_data[Energy Consumption]))/_xlfn.STDEV.P(sensor_data[Energy Consumption]) -> -0.19072141 | P29: =IF(ABS(sensor_data[[#This Row],[z_zcore]])>3, "Outlier", "Normal") -> Normal | Q29: =AVERAGEIF(sensor_data[Unit ID], sensor_data[[#This Row],[Unit ID]], sensor_data[EC]) -> 18.5915 | R29: =IF(ISBLANK(sensor_data[[#This Row],[EC]]), sensor_data[[#This Row],[average]], sensor_data[[#This Row],[EC]]) -> 5 | S29: =IF(sensor_data[[#This Row],[Filled Energy Consumption]]>AVERAGE(sensor_data[Filled Energy Consumption]), "High", "Low") -> Low | T29: T233 | U29: FALSE | V29: 8 | W29: 0 | X29: cooler
A30: 45432.687 | B30: =TEXT(sensor_data[[#This Row],[Timestamp]], "MMMM") -> May | C30: =IF(AND(HOUR(sensor_data[[#This Row],[Timestamp]])>=5, HOUR(sensor_data[[#This Row],[Timestamp]])<12), "Morning", IF(AND(HOUR(sensor_data[[#This Row],[Timestamp]])>=12, HOUR(sensor_data[[#This Row],[Timestamp]])<17), "Afternoon", IF(AND(HOUR(sensor_data[[#This Row],[Timestamp]])>=17, HOUR(sensor_data[[#This Row],[Timestamp]])<21), "Evening", "Night"))) -> Afternoon | D30: =MONTH(sensor_data[[#This Row],[Timestamp]]) -> 5 | E30: =DAY(sensor_data[[#This Row],[Timestamp]]) -> 20 | F30: U323 | H30: 75 | I30: 56.4 | J30: FALSE | K30: 1 | L30: =IF(sensor_data[[#This Row],[HVAC Setting]]<=2, "Low", IF(sensor_data[[#This Row],[HVAC Setting]]=3, "Normal", "High")) -> Low | M30: 5 | N30: 5 | O30: =(sensor_data[[#This Row],[Energy Consumption]]-AVERAGE(sensor_data[Energy Consumption]))/_xlfn.STDEV.P(sensor_data[Energy Consumption]) -> -0.19072141 | P30: =IF(ABS(sensor_data[[#This Row],[z_zcore]])>3, "Outlier", "Normal") -> Normal | Q30: =AVERAGEIF(sensor_data[Unit ID], sensor_data[[#This Row],[Unit ID]], sensor_data[EC]) -> 18.5915 | R30: =IF(ISBLANK(sensor_data[[#This Row],[EC]]), sensor_data[[#This Row],[average]], sensor_data[[#This Row],[EC]]) -> 5 | S30: =IF(sensor_data[[#This Row],[Filled Energy Consumption]]>AVERAGE(sensor_data[Filled Energy Consumption]), "High", "Low") -> Low | T30: T372 | U30: FALSE | V30: 19 | W30: 0 | X30: cooler
... A46: 45323.543 | B46: =TEXT(sensor_data[[#This Row],[Timestamp]], "MMMM") -> February | C46: =IF(AND(HOUR(sensor_data[[#This Row],[Timestamp]])>=5, HOUR(sensor_data[[#This Row],[Timestamp]])<12), "Morning", IF(AND(HOUR(sensor_data[[#This Row],[Timestamp]])>=12, HOUR(sensor_data[[#This Row],[Timestamp]])<17), "Afternoon", IF(AND(HOUR(sensor_data[[#This Row],[Timestamp]])>=17, HOUR(sensor_data[[#This Row],[Timestamp]])<21), "Evening", "Night"))) -> Afternoon | D46: =MONTH(sensor_data[[#This Row],[Timestamp]]) -> 2 | E46: =DAY(sensor_data[[#This Row],[Timestamp]]) -> 1 | F46: U403 | H46: 54.2 | I46: 35.3 | J46: FALSE | K46: 4 | L46: =IF(sensor_data[[#This Row],[HVAC Setting]]<=2, "Low", IF(sensor_data[[#This Row],[HVAC Setting]]=3, "Normal", "High")) -> High | M46: 20 | N46: 20 | O46: =(sensor_data[[#This Row],[Energy Consumption]]-AVERAGE(sensor_data[Energy Consumption]))/_xlfn.STDEV.P(sensor_data[Energy Consumption]) -> -0.016296635 | P46: =IF(ABS(sensor_data[[#This Row],[z_zcore]])>3, "Outlier", "Normal") -> Normal | Q46: =AVERAGEIF(sensor_data[Unit ID], sensor_data[[#This Row],[Unit ID]], sensor_data[EC]) -> 14.997059 | R46: =IF(ISBLANK(sensor_data[[#This Row],[EC]]), sensor_data[[#This Row],[average]], sensor_data[[#This Row],[EC]]) -> 20 | S46: =IF(sensor_data[[#This Row],[Filled Energy Consumption]]>AVERAGE(sensor_data[Filled Energy Consumption]), "High", "Low") -> High | T46: T419 | U46: FALSE | V46: 23 | W46: 0 | X46: cooler
A47: 45536.947 | B47: =TEXT(sensor_data[[#This Row],[Timestamp]], "MMMM") -> September | C47: =IF(AND(HOUR(sensor_data[[#This Row],[Timestamp]])>=5, HOUR(sensor_data[[#This Row],[Timestamp]])<12), "Morning", IF(AND(HOUR(sensor_data[[#This Row],[Timestamp]])>=12, HOUR(sensor_data[[#This Row],[Timestamp]])<17), "Afternoon", IF(AND(HOUR(sensor_data[[#This Row],[Timestamp]])>=17, HOUR(sensor_data[[#This Row],[Timestamp]])<21), "Evening", "Night"))) -> Night | D47: =MONTH(sensor_data[[#This Row],[Timestamp]]) -> 9 | E47: =DAY(sensor_data[[#This Row],[Timestamp]]) -> 1 | F47: U403 | H47: 69.7 | I47: 57.7 | J47: TRUE | K47: 2.5 | L47: =IF(sensor_data[[#This Row],[HVAC Setting]]<=2, "Low", IF(sensor_data[[#This Row],[HVAC Setting]]=3, "Normal", "High")) -> High | O47: =(sensor_data[[#This Row],[Energy Consumption]]-AVERAGE(sensor_data[Energy Consumption]))/_xlfn.STDEV.P(sensor_data[Energy Consumption]) -> -0.248863 | P47: =IF(ABS(sensor_data[[#This Row],[z_zcore]])>3, "Outlier", "Normal") -> Normal | Q47: =AVERAGEIF(sensor_data[Unit ID], sensor_data[[#This Row],[Unit ID]], sensor_data[EC]) -> 14.997059 | R47: =IF(ISBLANK(sensor_data[[#This Row],[EC]]), sensor_data[[#This Row],[average]], sensor_data[[#This Row],[EC]]) -> 14.997059 | S47: =IF(sensor_data[[#This Row],[Filled Energy Consumption]]>AVERAGE(sensor_data[Filled Energy Consumption]), "High", "Low") -> Low | T47: T158 | U47: TRUE | V47: 16 | W47: 1 | X47: cooler
A48: 45518.633 | B48: =TEXT(sensor_data[[#This Row],[Timestamp]], "MMMM") -> August | C48: =IF(AND(HOUR(sensor_data[[#This Row],[Timestamp]])>=5, HOUR(sensor_data[[#This Row],[Timestamp]])<12), "Morning", IF(AND(HOUR(sensor_data[[#This Row],[Timestamp]])>=12, HOUR(sensor_data[[#This Row],[Timestamp]])<17), "Afternoon", IF(AND(HOUR(sensor_data[[#This Row],[Timestamp]])>=17, HOUR(sensor_data[[#This Row],[Timestamp]])<21), "Evening", "Night"))) -> Afternoon | D48: =MONTH(sensor_data[[#This Row],[Timestamp]]) -> 8 | E48: =DAY(sensor_data[[#This Row],[Timestamp]]) -> 14 | F48: U403 | H48: 90.1 | I48: 63.6 | J48: TRUE | K48: 3 | L48: =IF(sensor_data[[#This Row],[HVAC Setting]]<=2, "Low", IF(sensor_data[[#This Row],[HVAC Setting]]=3, "Normal", "High")) -> Normal | M48: 18.38 | N48: 18.38 | O48: =(sensor_data[[#This Row],[Energy Consumption]]-AVERAGE(sensor_data[Energy Consumption]))/_xlfn.STDEV.P(sensor_data[Energy Consumption]) -> -0.035134511 | P48: =IF(ABS(sensor_data[[#This Row],[z_zcore]])>3, "Outlier", "Normal") -> Normal | Q48: =AVERAGEIF(sensor_data[Unit ID], sensor_data[[#This Row],[Unit ID]], sensor_data[EC]) -> 14.997059 | R48: =IF(ISBLANK(sensor_data[[#This Row],[EC]]), sensor_data[[#This Row],[average]], sensor_data[[#This Row],[EC]]) -> 18.38 | S48: =IF(sensor_data[[#This Row],[Filled Energy Consumption]]>AVERAGE(sensor_data[Filled Energy Consumption]), "High", "Low") -> High | T48: T129 | U48: TRUE | V48: 5 | W48: 0 | X48: neutral
A49: 45591.655 | B49: =TEXT(sensor_data[[#This Row],[Timestamp]], "MMMM") -> October | C49: =IF(AND(HOUR(sensor_data[[#This Row],[Timestamp]])>=5, HOUR(sensor_data[[#This Row],[Timestamp]])<12), "Morning", IF(AND(HOUR(sensor_data[[#This Row],[Timestamp]])>=12, HOUR(sensor_data[[#This Row],[Timestamp]])<17), "Afternoon", IF(AND(HOUR(sensor_data[[#This Row],[Timestamp]])>=17, HOUR(sensor_data[[#This Row],[Timestamp]])<21), "Evening", "Night"))) -> Afternoon | D49: =MONTH(sensor_data[[#This Row],[Timestamp]]) -> 10 | E49: =DAY(sensor_data[[#This Row],[Timestamp]]) -> 26 | F49: U403 | H49: 71.8 | I49: 46 | J49: TRUE | K49: 3.5 | L49: =IF(sensor_data[[#This Row],[HVAC Setting]]<=2, "Low", IF(sensor_data[[#This Row],[HVAC Setting]]=3, "Normal", "High")) -> High | O49: =(sensor_data[[#This Row],[Energy Consumption]]-AVERAGE(sensor_data[Energy Consumption]))/_xlfn.STDEV.P(sensor_data[Energy Consumption]) -> -0.248863 | P49: =IF(ABS(sensor_data[[#This Row],[z_zcore]])>3, "Outlier", "Normal") -> Normal | Q49: =AVERAGEIF(sensor_data[Unit ID], sensor_data[[#This Row],[Unit ID]], sensor_data[EC]) -> 14.997059 | R49: =IF(ISBLANK(sensor_data[[#This Row],[EC]]), sensor_data[[#This Row],[average]], sensor_data[[#This Row],[EC]]) -> 14.997059 | S49: =IF(sensor_data[[#This Row],[Filled Energy Consumption]]>AVERAGE(sensor_data[Filled Energy Consumption]), "High", "Low") -> Low | T49: T035 | U49: TRUE | V49: 24 | W49: 1 | X49: cooler
A50: 45503.803 | B50: =TEXT(sensor_data[[#This Row],[Timestamp]], "MMMM") -> July | C50: =IF(AND(HOUR(sensor_data[[#This Row],[Timestamp]])>=5, HOUR(sensor_data[[#This Row],[Timestamp]])<12), "Morning", IF(AND(HOUR(sensor_data[[#This Row],[Timestamp]])>=12, HOUR(sensor_data[[#This Row],[Timestamp]])<17), "Afternoon", IF(AND(HOUR(sensor_data[[#This Row],[Timestamp]])>=17, HOUR(sensor_data[[#This Row],[Timestamp]])<21), "Evening", "Night"))) -> Evening | D50: =MONTH(sensor_data[[#This Row],[Timestamp]]) -> 7 | E50: =DAY(sensor_data[[#This Row],[Timestamp]]) -> 30 | F50: U403 | H50: 98.6 | I50: 55.1 | J50: TRUE | K50: 5 | L50: =IF(sensor_data[[#This Row],[HVAC Setting]]<=2, "Low", IF(sensor_data[[#This Row],[HVAC Setting]]=3, "Normal", "High")) -> High | O50: =(sensor_data[[#This Row],[Energy Consumption]]-AVERAGE(sensor_data[Energy Consumption]))/_xlfn.STDEV.P(sensor_data[Energy Consumption]) -> -0.248863 | P50: =IF(ABS(sensor_data[[#This Row],[z_zcore]])>3, "Outlier", "Normal") -> Normal | Q50: =AVERAGEIF(sensor_data[Unit ID], sensor_data[[#This Row],[Unit ID]], sensor_data[EC]) -> 14.997059 | R50: =IF(ISBLANK(sensor_data[[#This Row],[EC]]), sensor_data[[#This Row],[average]], sensor_data[[#This Row],[EC]]) -> 14.997059 | S50: =IF(sensor_data[[#This Row],[Filled Energy Consumption]]>AVERAGE(sensor_data[Filled Energy Consumption]), "High", "Low") -> Low | T50: T188 | U50: TRUE | V50: 19 | W50: 1 | X50: neutral
A51: 45574.482 | B51: =TEXT(sensor_data[[#This Row],[Timestamp]], "MMMM") -> October | C51: =IF(AND(HOUR(sensor_data[[#This Row],[Timestamp]])>=5, HOUR(sensor_data[[#This Row],[Timestamp]])<12), "Morning", IF(AND(HOUR(sensor_data[[#This Row],[Timestamp]])>=12, HOUR(sensor_data[[#This Row],[Timestamp]])<17), "Afternoon", IF(AND(HOUR(sensor_data[[#This Row],[Timestamp]])>=17, HOUR(sensor_data[[#This Row],[Timestamp]])<21), "Evening", "Night"))) -> Morning | D51: =MONTH(sensor_data[[#This Row],[Timestamp]]) -> 10 | E51: =DAY(sensor_data[[#This Row],[Timestamp]]) -> 9 | F51: U403 | H51: 78.8 | I51: 55.4 | J51: FALSE | K51: 2 | L51: =IF(sensor_data[[#This Row],[HVAC Setting]]<=2, "Low", IF(sensor_data[[#This Row],[HVAC Setting]]=3, "Normal", "High")) -> Low | M51: 10 | N51: 10 | O51: =(sensor_data[[#This Row],[Energy Consumption]]-AVERAGE(sensor_data[Energy Consumption]))/_xlfn.STDEV.P(sensor_data[Energy Consumption]) -> -0.13257982 | P51: =IF(ABS(sensor_data[[#This Row],[z_zcore]])>3, "Outlier", "Normal") -> Normal | Q51: =AVERAGEIF(sensor_data[Unit ID], sensor_data[[#This Row],[Unit ID]], sensor_data[EC]) -> 14.997059 | R51: =IF(ISBLANK(sensor_data[[#This Row],[EC]]), sensor_data[[#This Row],[average]], sensor_data[[#This Row],[EC]]) -> 10 | S51: =IF(sensor_data[[#This Row],[Filled Energy Consumption]]>AVERAGE(sensor_data[Filled Energy Consumption]), "High", "Low") -> Low | T51: T185 | U51: FALSE | V51: 14 | W51: 0 | X51: cooler
A52: 45649.646 | B52: =TEXT(sensor_data[[#This Row],[Timestamp]], "MMMM") -> December | C52: =IF(AND(HOUR(sensor_data[[#This Row],[Timestamp]])>=5, HOUR(sensor_data[[#This Row],[Timestamp]])<12), "Morning", IF(AND(HOUR(sensor_data[[#This Row],[Timestamp]])>=12, HOUR(sensor_data[[#This Row],[Timestamp]])<17), "Afternoon", IF(AND(HOUR(sensor_data[[#This Row],[Timestamp]])>=17, HOUR(sensor_data[[#This Row],[Timestamp]])<21), "Evening", "Night"))) -> Afternoon | D52: =MONTH(sensor_data[[#This Row],[Timestamp]]) -> 12 | E52: =DAY(sensor_data[[#This Row],[Timestamp]]) -> 23 | F52: U403 | H52: 40 | I52: 38.5 | J52: TRUE | K52: 4 | L52: =IF(sensor_data[[#This Row],[HVAC Setting]]<=2, "Low", IF(sensor_data[[#This Row],[HVAC Setting]]=3, "Normal", "High")) -> High | M52: 23.82 | N52: 23.82 | O52: =(sensor_data[[#This Row],[Energy Consumption]]-AVERAGE(sensor_data[Energy Consumption]))/_xlfn.STDEV.P(sensor_data[Energy Consumption]) -> 0.028123539 | P52: =IF(ABS(sensor_data[[#This Row],[z_zcore]])>3, "Outlier", "Normal") -> Normal | Q52: =AVERAGEIF(sensor_data[Unit ID], sensor_data[[#This Row],[Unit ID]], sensor_data[EC]) -> 14.997059 | R52: =IF(ISBLANK(sensor_data[[#This Row],[EC]]), sensor_data[[#This Row],[average]], sensor_data[[#This Row],[EC]]) -> 23.82 | S52: =IF(sensor_data[[#This Row],[Filled Energy Consumption]]>AVERAGE(sensor_data[Filled Energy Consumption]), "High", "Low") -> High | T52: T402 | U52: TRUE | V52: 1 | W52: 1 | X52: neutral
A53: 45443.403 | B53: =TEXT(sensor_data[[#This Row],[Timestamp]], "MMMM") -> May | C53: =IF(AND(HOUR(sensor_data[[#This Row],[Timestamp]])>=5, HOUR(sensor_data[[#This Row],[Timestamp]])<12), "Morning", IF(AND(HOUR(sensor_data[[#This Row],[Timestamp]])>=12, HOUR(sensor_data[[#This Row],[Timestamp]])<17), "Afternoon", IF(AND(HOUR(sensor_data[[#This Row],[Timestamp]])>=17, HOUR(sensor_data[[#This Row],[Timestamp]])<21), "Evening", "Night"))) -> Morning | D53: =MONTH(sensor_data[[#This Row],[Timestamp]]) -> 5 | E53: =DAY(sensor_data[[#This Row],[Timestamp]]) -> 31 | F53: U403 | H53: 65.1 | I53: 41.7 | J53: FALSE | K53: 2 | L53: =IF(sensor_data[[#This Row],[HVAC Setting]]<=2, "Low", IF(sensor_data[[#This Row],[HVAC Setting]]=3, "Normal", "High")) -> Low | M53: 10 | N53: 10 | O53: =(sensor_data[[#This Row],[Energy Consumption]]-AVERAGE(sensor_data[Energy Consumption]))/_xlfn.STDEV.P(sensor_data[Energy Consumption]) -> -0.13257982 | P53: =IF(ABS(sensor_data[[#This Row],[z_zcore]])>3, "Outlier", "Normal") -> Normal | Q53: =AVERAGEIF(sensor_data[Unit ID], sensor_data[[#This Row],[Unit ID]], sensor_data[EC]) -> 14.997059 | R53: =IF(ISBLANK(sensor_data[[#This Row],[EC]]), sensor_data[[#This Row],[average]], sensor_data[[#This Row],[EC]]) -> 10 | S53: =IF(sensor_data[[#This Row],[Filled Energy Consumption]]>AVERAGE(sensor_data[Filled Energy Consumption]), "High", "Low") -> Low | T53: T068 | U53: FALSE | V53: 5 | W53: 0 | X53: cooler
A54: 45550.482 | B54: =TEXT(sensor_data[[#This Row],[Timestamp]], "MMMM") -> September | C54: =IF(AND(HOUR(sensor_data[[#This Row],[Timestamp]])>=5, HOUR(sensor_data[[#This Row],[Timestamp]])<12), "Morning", IF(AND(HOUR(sensor_data[[#This Row],[Timestamp]])>=12, HOUR(sensor_data[[#This Row],[Timestamp]])<17), "Afternoon", IF(AND(HOUR(sensor_data[[#This Row],[Timestamp]])>=17, HOUR(sensor_data[[#This Row],[Timestamp]])<21), "Evening", "Night"))) -> Morning | D54: =MONTH(sensor_data[[#This Row],[Timestamp]]) -> 9 | E54: =DAY(sensor_data[[#This Row],[Timestamp]]) -> 15 | F54: U403 | H54: 80.5 | I54: 30.6 | J54: TRUE | K54: 3.5 | L54: =IF(sensor_data[[#This Row],[HVAC Setting]]<=2, "Low", IF(sensor_data[[#This Row],[HVAC Setting]]=3, "Normal", "High")) -> High | M54: 20.49 | N54: 20.49 | O54: =(sensor_data[[#This Row],[Energy Consumption]]-AVERAGE(sensor_data[Energy Consumption]))/_xlfn.STDEV.P(sensor_data[Energy Consumption]) -> -0.01059876 | P54: =IF(ABS(sensor_data[[#This Row],[z_zcore]])>3, "Outlier", "Normal") -> Normal | Q54: =AVERAGEIF(sensor_data[Unit ID], sensor_data[[#This Row],[Unit ID]], sensor_data[EC]) -> 14.997059 | R54: =IF(ISBLANK(sensor_data[[#This Row],[EC]]), sensor_data[[#This Row],[average]], sensor_data[[#This Row],[EC]]) -> 20.49 | S54: =IF(sensor_data[[#This Row],[Filled Energy Consumption]]>AVERAGE(sensor_data[Filled Energy Consumption]), "High", "Low") -> High | T54: T289 | U54: TRUE | V54: 23 | W54: 1 | X54: cooler
A55: 45389.238 | B55: =TEXT(sensor_data[[#This Row],[Timestamp]], "MMMM") -> April | C55: =IF(AND(HOUR(sensor_data[[#This Row],[Timestamp]])>=5, HOUR(sensor_data[[#This Row],[Timestamp]])<12), "Morning", IF(AND(HOUR(sensor_data[[#This Row],[Timestamp]])>=12, HOUR(sensor_data[[#This Row],[Timestamp]])<17), "Afternoon", IF(AND(HOUR(sensor_data[[#This Row],[Timestamp]])>=17, HOUR(sensor_data[[#This Row],[Timestamp]])<21), "Evening", "Night"))) -> Morning | D55: =MONTH(sensor_data[[#This Row],[Timestamp]]) -> 4 | E55: =DAY(sensor_data[[#This Row],[Timestamp]]) -> 7 | F55: U403 | H55: 67 | I55: 32.4 | J55: FALSE | K55: 0.5 | L55: =IF(sensor_data[[#This Row],[HVAC Setting]]<=2, "Low", IF(sensor_data[[#This Row],[HVAC Setting]]=3, "Normal", "High")) -> Low | M55: 3.68 | N55: 3.68 | O55: =(sensor_data[[#This Row],[Energy Consumption]]-AVERAGE(sensor_data[Energy Consumption]))/_xlfn.STDEV.P(sensor_data[Energy Consumption]) -> -0.20607079 | P55: =IF(ABS(sensor_data[[#This Row],[z_zcore]])>3, "Outlier", "Normal") -> Normal | Q55: =AVERAGEIF(sensor_data[Unit ID], sensor_data[[#This Row],[Unit ID]], sensor_data[EC]) -> 14.997059 | R55: =IF(ISBLANK(sensor_data[[#This Row],[EC]]), sensor_data[[#This Row],[average]], sensor_data[[#This Row],[EC]]) -> 3.68 | S55: =IF(sensor_data[[#This Row],[Filled Energy Consumption]]>AVERAGE(sensor_data[Filled Energy Consumption]), "High", "Low") -> Low | T55: T131 | U55: FALSE | V55: 18 | W55: 0 | X55: cooler
...

Sheet maintenance_logs
A1: Maintenance ID | B1: Unit ID | C1: Issue Type | D1: Resolution | E1: Log Date | F1: average EC
A2: M027 | B2: U001 | C2: HVAC failure | D2: Cleaning | E2: 45319.942 | F2: =AVERAGEIF(sensor_data[Unit ID], maintenance_logs[[#This Row],[Unit ID]],sensor_data!R:R) -> 15.251053
A3: M319 | B3: U001 | C3: HVAC failure | D3: Part replacement | E3: 45647.928 | F3: =AVERAGEIF(sensor_data[Unit ID], maintenance_logs[[#This Row],[Unit ID]],sensor_data!R:R) -> 15.251053
A4: M035 | B4: U002 | C4: Filter replacement | D4: Part replacement | E4: 45332.764 | F4: =AVERAGEIF(sensor_data[Unit ID], maintenance_logs[[#This Row],[Unit ID]],sensor_data!R:R) -> 20.743333
A5: M100 | B5: U002 | C5: HVAC failure | D5: Part replacement | E5: 45403.092 | F5: =AVERAGEIF(sensor_data[Unit ID], maintenance_logs[[#This Row],[Unit ID]],sensor_data!R:R) -> 20.743333
A6: M108 | B6: U002 | C6: HVAC failure | D6: Part replacement | E6: 45409.985 | F6: =AVERAGEIF(sensor_data[Unit ID], maintenance_logs[[#This Row],[Unit ID]],sensor_data!R:R) -> 20.743333
A7: M201 | B7: U006 | C7: Filter replacement | D7: Cleaning | E7: 45520.601 | F7: =AVERAGEIF(sensor_data[Unit ID], maintenance_logs[[#This Row],[Unit ID]],sensor_data!R:R) -> 18.3565
A8: M018 | B8: U007 | C8: Lighting fixture failure | D8: Cleaning | E8: 45312.31 | F8: =AVERAGEIF(sensor_data[Unit ID], maintenance_logs[[#This Row],[Unit ID]],sensor_data!R:R) -> 18.4135
